<?xml version="1.0" encoding="utf-8"?>

<robot name="wheely_robot" xmlns:xacro="http://www.ros.org/wiki/xacro">

  <xacro:include filename="inertial_macros.xacro"/>
  <xacro:include filename="materials.xacro"/>
  <xacro:include filename="wheely.gazebo"/>

  <!-- Robot Links -->

  <link name="wheely_base_link">
    <xacro:inertial_box mass="0.1" x="0.2" y="0.1" z="0.05">
      <origin xyz="0 0 0" rpy="0 0 0"/>
    </xacro:inertial_box>
    <visual>
      <origin xyz="0 0 0.01" rpy="0 0 0" />
      <geometry>
        <box size="0.2 0.1 0.05"/>
      </geometry>
      <material name="red"/>
    </visual>
    <collision>
      <origin xyz="0 0 0" rpy="0 0 0" />
      <geometry>
        <box size="0.2 0.1 0.05"/>
      </geometry>
    </collision>
  </link>

  <link name="aruco_link">
    <inertial>
      <origin xyz="0 0 0" rpy="0 0 0"/>
      <mass value="0.001" />
      <inertia ixx="0.00741666666667" ixy="0.0" ixz="0.0" iyy="0.00585416666667" iyz="0.0" izz="0.00260416666667"/>
    </inertial>
    <collision>
      <origin xyz="0 0 0" rpy="0 0 0"/>
      <geometry>
        <box size="0.1 0.1 0.001"/>
      </geometry>
    </collision>
    <visual>
      <origin rpy="0.0 0 0" xyz="0 0 0"/>
      <geometry>
        <!--<box size="0.8 0.8 0.2"/>-->
        <mesh filename="package://wheely_robot/meshes/ar_2020_v2.dae"/>
      </geometry>
    </visual>
  </link>

  <joint name="aruco_joint" type="fixed">
    <parent link="wheely_base_link"/>
    <child link="aruco_link"/>
    <origin xyz="0 0 0.03" rpy="${pi} 0 0" />
  </joint>

  <link name="front_left_wheel">
    <xacro:inertial_cylinder mass="0.05" length="0.05" radius="0.05">
      <origin xyz="0 0 0" rpy="0 0 0"/>
    </xacro:inertial_cylinder>
    <visual>
      <origin xyz="0 0 0" rpy="0 0 0" />
      <geometry>
        <cylinder length="0.05" radius="0.05"/>
      </geometry>
      <material name="black"/>
    </visual>
    <collision>
      <origin xyz="0 0 0" rpy="0 0 0" />
      <geometry>
        <cylinder length="0.05" radius="0.05"/>
      </geometry>
    </collision>
  </link>

  <joint name="front_left_wheel_joint" type="continuous">
    <parent link="wheely_base_link"/>
    <child link="front_left_wheel"/>
    <origin xyz="0.1 -0.075 0" rpy="-${pi/2} 0 0" />
    <axis xyz="0 0 1"/>
  </joint>

  <link name="front_right_wheel">
    <xacro:inertial_cylinder mass="0.05" length="0.05" radius="0.05">
      <origin xyz="0 0 0" rpy="0 0 0"/>
    </xacro:inertial_cylinder>
    <visual>
      <origin xyz="0 0 0" rpy="0 0 0" />
      <geometry>
        <cylinder length="0.05" radius="0.05"/>
      </geometry>
      <material name="black"/>
    </visual>
    <collision>
      <origin xyz="0 0 0" rpy="0 0 0" />
      <geometry>
        <cylinder length="0.05" radius="0.05"/>
      </geometry>
    </collision>
  </link>

  <joint name="front_right_wheel_joint" type="continuous">
    <parent link="wheely_base_link"/>
    <child link="front_right_wheel"/>
    <origin xyz="0.1 0.075 0" rpy="-${pi/2} 0 0" />
    <axis xyz="0 0 1"/>
  </joint>

  <link name="rear_left_wheel">
    <xacro:inertial_cylinder mass="0.05" length="0.05" radius="0.05">
      <origin xyz="0 0 0" rpy="0 0 0"/>
    </xacro:inertial_cylinder>
    <visual>
      <origin xyz="0 0 0" rpy="0 0 0" />
      <geometry>
        <cylinder length="0.05" radius="0.05"/>
      </geometry>
      <material name="black"/>
    </visual>
    <collision>
      <origin xyz="0 0 0" rpy="0 0 0" />
      <geometry>
        <cylinder length="0.05" radius="0.05"/>
      </geometry>
    </collision>
  </link>

  <joint name="rear_left_wheel_joint" type="continuous">
    <parent link="wheely_base_link"/>
    <child link="rear_left_wheel"/>
    <origin xyz="-0.1 -0.075 0" rpy="-${pi/2} 0 0" />
    <axis xyz="0 0 1"/>
  </joint>

  <link name="rear_right_wheel">
    <xacro:inertial_cylinder mass="0.05" length="0.05" radius="0.05">
      <origin xyz="0 0 0" rpy="0 0 0"/>
    </xacro:inertial_cylinder>
    <visual>
      <origin xyz="0 0 0" rpy="0 0 0" />
      <geometry>
        <cylinder length="0.05" radius="0.05"/>
      </geometry>
      <material name="black"/>
    </visual>
    <collision>
      <origin xyz="0 0 0" rpy="0 0 0" />
      <geometry>
        <cylinder length="0.05" radius="0.05"/>
      </geometry>
    </collision>
  </link>

  <joint name="rear_right_wheel_joint" type="continuous">
    <parent link="wheely_base_link"/>
    <child link="rear_right_wheel"/>
    <origin xyz="-0.1 0.075 0" rpy="-${pi/2} 0 0" />
    <axis xyz="0 0 1"/>
  </joint>

</robot>
